Workbook
Name datos: #REF!
Name datos: #REF!
Name datos: #REF!
Name errores: #REF!
Name errores: #REF!
Name errores: #REF!

Sheet BD Centrales 2025
A1: ID Central infotécnica | B1: Nemotécnico Central Infotécnica | C1: Nombre Central Infotécnica | D1: Coordinado | E1: RUT Coordinado | F1: Propietario | G1: N° Centrales del coordinado | H1: POI | I1: POI CMg | J1: BARRA_TRANSF | K1: Cantidad de unidades | L1: Año | M1: Tipo de central | N1: Tipo tecnología | O1: Medio de generación | P1: Región | Q1: Provincia | R1: Comuna | S1: Estado | T1: Fecha EO | U1: Potencia máxima bruta Central [MW] | V1: Potencia máxima neta Central [MW] | W1: Inyección energía [GWh] | X1: Retiros energía Bloque A [MWh] | Y1: Retiros energía Bloque B [MWh] | Z1: Retiros energía Bloque C [MWh] | AA1: Retiros energía Total 2025 [MWh] | AB1: CMg precio captura | AC1: CMg promedio horario | AD1: CMg promedio solar | AE1: CMg promedio noche | AF1: Porcentaje iny. costo cero | AG1: Pagos laterales | AH1: Ingresos Energía Coordinado (Balance) | AI1: Ingresos Potencia Coordinado | AJ1: Ingresos SSCC Coordinado | AK1: PPA mínimo | AL1: Ingresos Estimados PPA | AM1: Ingresos energía (balance + PPA) | AN1: Ingresos Totales [USD/MWh]
A2: 0 | B2: CE05G0265 | C2: PFV MALGARIDA | D2: ACCIONA ENERGÍA CHILE HOLDINGS S.A. | E2: =_xlfn.XLOOKUP(D2,'[2]Coordinados SEN'!$A:$A,'[2]Coordinados SEN'!$B:$B,"-",0) -> 76.437.712-5 | F2: ACCIONA ENERGÍA CHILE HOLDINGS S.A. | G2: =COUNTIFS($D$2:$D$1194,D2) -> 6 | H2: ID2284-S/E MALGARIDA | I2: S/E MALGARIDA 220KV | J2: =_xlfn.XLOOKUP(I2,'[2]Barras CMg'!$E$2:$E$1527,'[2]Barras CMg'!$A$2:$A$1527,"------",0,1) -> MALGARIDA_____220 | K2: 1 | L2: 2025 | M2: Fotovoltaica | N2: Parque fotovoltaico | O2: Instalaciones de generación | P2: Atacama | Q2: Chañaral | R2: Diego de Almagro | S2: Operativa | T2: 19-06-2021 | U2: 204.32 | V2: 200.68 | W2: =_xlfn.XLOOKUP(C2,#REF!,#REF!,"S/I",0) -> #REF! | X2: =_xlfn.XLOOKUP($D2,[2]Retiros_dinamica!$F:$F,[2]Retiros_dinamica!B:B,"S/I",0) -> 448325.71 | Y2: =_xlfn.XLOOKUP($D2,[2]Retiros_dinamica!$F:$F,[2]Retiros_dinamica!C:C,"S/I",0) -> 508026.01 | Z2: =_xlfn.XLOOKUP($D2,[2]Retiros_dinamica!$F:$F,[2]Retiros_dinamica!D:D,"S/I",0) -> 259394.42 | AA2: =_xlfn.XLOOKUP($D2,[2]Retiros_dinamica!$F:$F,[2]Retiros_dinamica!E:E,"S/I",0) -> 1215746.1 | AB2: =_xlfn.XLOOKUP(C2,[2]CMg!$I$4:$I$106,[2]CMg!$M$4:$M$106,"----",0,1) -> 7.4844658 | AC2: =_xlfn.XLOOKUP(C2,'[3]Promedio Cmg'!$A$4:$A$106,'[3]Promedio Cmg'!$B$4:$B$106,"---",0,1) -> 48.996233 | AD2: =_xlfn.XLOOKUP(C2,'[3]Promedio solar Cmg'!$A$4:$A$106,'[3]Promedio solar Cmg'!$B$4:$B$106,"----",0,1) -> 9.320074 | AE2: =_xlfn.XLOOKUP(C2,[2]CMg!$O$4:$O$106,[2]CMg!$P$4:$P$106,"----",0,1) -> 77.330802 | AF2: =_xlfn.XLOOKUP(C2,[2]CMg!$S$4:$S$106,[2]CMg!$U$4:$U$106,"----",0,1) -> 0.46124872 | AH2: =_xlfn.XLOOKUP($E2,'[2]Balance económico'!$C:$C,'[2]Balance económico'!$D:$D,"-",0) -> -6.7605287e+10 | AI2: =_xlfn.XLOOKUP($E2,'[2]Balance económico'!$C:$C,'[2]Balance económico'!$E:$E,"-",0) -> -1.1939622e+10 | AJ2: =_xlfn.XLOOKUP($E2,'[2]Balance económico'!$C:$C,'[2]Balance económico'!$F:$F,"-",0) -> 4.7816583e+09 | AK2: =IF(AA2>0,"PPA","-") -> PPA | AL2: {=IFERROR((X2*[2]!Tabla2[Bloque A] + 'BD Centrales 2025'!Y934*[2]!Tabla2[Bloque B] + 'BD Centrales 2025'!Z934*[2]!Tabla2[Bloque C])*#REF!,"-")} -> - | AM2: =IFERROR(AH2+AL2,"-") -> - | AN2: =IFERROR((AH2+AI2+AJ2)/(SUMIFS($W$2:$W$1194,$E$2:$E$1194,E2)*1000*#REF!),0) -> 0
A3: 2 | B3: CE06G0035 | C3: TER MAULE | D3: ELEKTRA GENERACIÓN S.A. | E3: =_xlfn.XLOOKUP(D3,'[2]Coordinados SEN'!$A:$A,'[2]Coordinados SEN'!$B:$B,"-",0) -> 76.594.660-3 | F3: ELEKTRA GENERACIÓN S.A. | G3: =COUNTIFS($D$2:$D$1194,D3) -> 5 | H3: S/E CONSTITUCION 23KV | I3: S/E CONSTITUCION 23KV | J3: =_xlfn.XLOOKUP(I3,'[2]Barras CMg'!$E$2:$E$1527,'[2]Barras CMg'!$A$2:$A$1527,"------",0,1) -> CONSTIT1______023 | K3: 6 | L3: 2025 | M3: Termoeléctrica | N3: Motor de combustión interna | O3: Pequeños medio de generación o PMG | P3: Maule | Q3: Talca | R3: Constitución | S3: Operativa | T3: 07-06-2007 | U3: 6.099 | V3: 5.959 | W3: =_xlfn.XLOOKUP(C3,#REF!,#REF!,"S/I",0) -> #REF! | X3: =_xlfn.XLOOKUP($D3,[2]Retiros_dinamica!$F:$F,[2]Retiros_dinamica!B:B,"S/I",0) -> S/I | Y3: =_xlfn.XLOOKUP($D3,[2]Retiros_dinamica!$F:$F,[2]Retiros_dinamica!C:C,"S/I",0) -> S/I | Z3: =_xlfn.XLOOKUP($D3,[2]Retiros_dinamica!$F:$F,[2]Retiros_dinamica!D:D,"S/I",0) -> S/I | AA3: =_xlfn.XLOOKUP($D3,[2]Retiros_dinamica!$F:$F,[2]Retiros_dinamica!E:E,"S/I",0) -> S/I | AB3: =_xlfn.XLOOKUP(C3,[2]CMg!$I$4:$I$106,[2]CMg!$M$4:$M$106,"----",0,1) -> ---- | AH3: =_xlfn.XLOOKUP($E3,'[2]Balance económico'!$C:$C,'[2]Balance económico'!$D:$D,"-",0) -> 1.0058747e+09 | AI3: =_xlfn.XLOOKUP($E3,'[2]Balance económico'!$C:$C,'[2]Balance económico'!$E:$E,"-",0) -> 2.3067282e+09 | AJ3: =_xlfn.XLOOKUP($E3,'[2]Balance económico'!$C:$C,'[2]Balance económico'!$F:$F,"-",0) -> ---- | AK3: =IF(AA3>0,"PPA","-") -> PPA | AL3: {=IFERROR((X3*[2]!Tabla2[Bloque A] + 'BD Centrales 2025'!Y1143*[2]!Tabla2[Bloque B] + 'BD Centrales 2025'!Z1143*[2]!Tabla2[Bloque C])*#REF!,"-")} -> - | AM3: =IFERROR(AH3+AL3,"-") -> - | AN3: =IFERROR((AH3+AI3+AJ3)/(SUMIFS($W$2:$W$1194,$E$2:$E$1194,E3)*1000*#REF!),0) -> 0
A4: 3 | B4: CE05G0035 | C4: TER CHILOE | D4: ELEKTRA GENERACIÓN S.A. | E4: =_xlfn.XLOOKUP(D4,'[2]Coordinados SEN'!$A:$A,'[2]Coordinados SEN'!$B:$B,"-",0) -> 76.594.660-3 | F4: ELEKTRA GENERACIÓN S.A. | G4: =COUNTIFS($D$2:$D$1194,D4) -> 5 | H4: S/E QUELLON 23KV | I4: S/E QUELLON 110KV | J4: =_xlfn.XLOOKUP(I4,'[2]Barras CMg'!$E$2:$E$1527,'[2]Barras CMg'!$A$2:$A$1527,"------",0,1) -> QUELLON_______110 | K4: 9 | L4: 2025 | M4: Termoeléctrica | N4: Motor de combustión interna | O4: Pequeños medio de generación o PMG | P4: Los Lagos | Q4: Chiloé | R4: Quellón | S4: Operativa | T4: 16-07-2008 | U4: 9.227 | V4: 9.056 | W4: =_xlfn.XLOOKUP(C4,#REF!,#REF!,"S/I",0) -> #REF! | X4: =_xlfn.XLOOKUP($D4,[2]Retiros_dinamica!$F:$F,[2]Retiros_dinamica!B:B,"S/I",0) -> S/I | Y4: =_xlfn.XLOOKUP($D4,[2]Retiros_dinamica!$F:$F,[2]Retiros_dinamica!C:C,"S/I",0) -> S/I | Z4: =_xlfn.XLOOKUP($D4,[2]Retiros_dinamica!$F:$F,[2]Retiros_dinamica!D:D,"S/I",0) -> S/I | AA4: =_xlfn.XLOOKUP($D4,[2]Retiros_dinamica!$F:$F,[2]Retiros_dinamica!E:E,"S/I",0) -> S/I | AB4: =_xlfn.XLOOKUP(C4,[2]CMg!$I$4:$I$106,[2]CMg!$M$4:$M$106,"----",0,1) -> ---- | AH4: =_xlfn.XLOOKUP($E4,'[2]Balance económico'!$C:$C,'[2]Balance económico'!$D:$D,"-",0) -> 1.0058747e+09 | AI4: =_xlfn.XLOOKUP($E4,'[2]Balance económico'!$C:$C,'[2]Balance económico'!$E:$E,"-",0) -> 2.3067282e+09 | AJ4: =_xlfn.XLOOKUP($E4,'[2]Balance económico'!$C:$C,'[2]Balance económico'!$F:$F,"-",0) -> ---- | AK4: =IF(AA4>0,"PPA","-") -> PPA | AL4: {=IFERROR((X4*[2]!Tabla2[Bloque A] + 'BD Centrales 2025'!Y1009*[2]!Tabla2[Bloque B] + 'BD Centrales 2025'!Z1009*[2]!Tabla2[Bloque C])*#REF!,"-")} -> - | AM4: =IFERROR(AH4+AL4,"-") -> - | AN4: =IFERROR((AH4+AI4+AJ4)/(SUMIFS($W$2:$W$1194,$E$2:$E$1194,E4)*1000*#REF!),0) -> 0
A5: 4 | B5: CE01G0035 | C5: TER CONSTITUCION | D5: ELEKTRA GENERACIÓN S.A. | E5: =_xlfn.XLOOKUP(D5,'[2]Coordinados SEN'!$A:$A,'[2]Coordinados SEN'!$B:$B,"-",0) -> 76.594.660-3 | F5: ELEKTRA GENERACIÓN S.A. | G5: =COUNTIFS($D$2:$D$1194,D5) -> 5 | H5: S/E CONSTITUCION 23KV | I5: S/E CONSTITUCION 23KV | J5: =_xlfn.XLOOKUP(I5,'[2]Barras CMg'!$E$2:$E$1527,'[2]Barras CMg'!$A$2:$A$1527,"------",0,1) -> CONSTIT1______023 | K5: 6 | L5: 2025 | M5: Termoeléctrica | N5: Motor de combustión interna | O5: Pequeños medio de generación o PMG | P5: Maule | Q5: Talca | R5: Constitución | S5: Operativa | T5: 06-06-2007 | U5: 9.593 | V5: 9.012 | W5: =_xlfn.XLOOKUP(C5,#REF!,#REF!,"S/I",0) -> #REF! | X5: =_xlfn.XLOOKUP($D5,[2]Retiros_dinamica!$F:$F,[2]Retiros_dinamica!B:B,"S/I",0) -> S/I | Y5: =_xlfn.XLOOKUP($D5,[2]Retiros_dinamica!$F:$F,[2]Retiros_dinamica!C:C,"S/I",0) -> S/I | Z5: =_xlfn.XLOOKUP($D5,[2]Retiros_dinamica!$F:$F,[2]Retiros_dinamica!D:D,"S/I",0) -> S/I | AA5: =_xlfn.XLOOKUP($D5,[2]Retiros_dinamica!$F:$F,[2]Retiros_dinamica!E:E,"S/I",0) -> S/I | AB5: =_xlfn.XLOOKUP(C5,[2]CMg!$I$4:$I$106,[2]CMg!$M$4:$M$106,"----",0,1) -> ---- | AH5: =_xlfn.XLOOKUP($E5,'[2]Balance económico'!$C:$C,'[2]Balance económico'!$D:$D,"-",0) -> 1.0058747e+09 | AI5: =_xlfn.XLOOKUP($E5,'[2]Balance económico'!$C:$C,'[2]Balance económico'!$E:$E,"-",0) -> 2.3067282e+09 | AJ5: =_xlfn.XLOOKUP($E5,'[2]Balance económico'!$C:$C,'[2]Balance económico'!$F:$F,"-",0) -> ---- | AK5: =IF(AA5>0,"PPA","-") -> PPA | AL5: {=IFERROR((X5*[2]!Tabla2[Bloque A] + 'BD Centrales 2025'!Y1075*[2]!Tabla2[Bloque B] + 'BD Centrales 2025'!Z1075*[2]!Tabla2[Bloque C])*#REF!,"-")} -> - | AM5: =IFERROR(AH5+AL5,"-") -> - | AN5: =IFERROR((AH5+AI5+AJ5)/(SUMIFS($W$2:$W$1194,$E$2:$E$1194,E5)*1000*#REF!),0) -> 0
A6: 5 | B6: CE01G0071 | C6: HP MARIPOSAS | D6: HIDROELÉCTRICA RÍO LIRCAY S.A. | E6: =_xlfn.XLOOKUP(D6,'[2]Coordinados SEN'!$A:$A,'[2]Coordinados SEN'!$B:$B,"-",0) -> 76.025.973-K | F6: HIDROELÉCTRICA RÍO LIRCAY S.A. | G6: =COUNTIFS($D$2:$D$1194,D6) -> 3 | H6: ID 1174 BA S/E MARIPOSAS 66KV BP1 | I6: S/E CENTRAL LIRCAY 66KV | J6: =_xlfn.XLOOKUP(I6,'[2]Barras CMg'!$E$2:$E$1527,'[2]Barras CMg'!$A$2:$A$1527,"------",0,1) -> LIRCAY________066 | K6: 1 | L6: 2025 | M6: Hidroeléctrica | N6: Minihidro de pasada | O6: Pequeños medio de generación o PMG | P6: Maule | Q6: Talca | R6: San Clemente | S6: Operativa – Autodespacho DS88 | T6: 26-03-2011 | U6: 6.3 | V6: 6.2855 | W6: =_xlfn.XLOOKUP(C6,#REF!,#REF!,"S/I",0) -> #REF! | X6: =_xlfn.XLOOKUP($D6,[2]Retiros_dinamica!$F:$F,[2]Retiros_dinamica!B:B,"S/I",0) -> S/I | Y6: =_xlfn.XLOOKUP($D6,[2]Retiros_dinamica!$F:$F,[2]Retiros_dinamica!C:C,"S/I",0) -> S/I | Z6: =_xlfn.XLOOKUP($D6,[2]Retiros_dinamica!$F:$F,[2]Retiros_dinamica!D:D,"S/I",0) -> S/I | AA6: =_xlfn.XLOOKUP($D6,[2]Retiros_dinamica!$F:$F,[2]Retiros_dinamica!E:E,"S/I",0) -> S/I | AB6: =_xlfn.XLOOKUP(C6,[2]CMg!$I$4:$I$106,[2]CMg!$M$4:$M$106,"----",0,1) -> ---- | AC6: =_xlfn.XLOOKUP(C6,[2]CMg!$A$4:$A$106,[2]CMg!$B$4:$B$106,"----",0,1) -> ---- | AD6: =_xlfn.XLOOKUP(C6,'[3]Promedio solar Cmg'!$A$4:$A$106,'[3]Promedio solar Cmg'!$B$4:$B$106,"----",0,1) -> ---- | AH6: =_xlfn.XLOOKUP($E6,'[2]Balance económico'!$C:$C,'[2]Balance económico'!$D:$D,"-",0) -> 2.4186895e+09 | AI6: =_xlfn.XLOOKUP($E6,'[2]Balance económico'!$C:$C,'[2]Balance económico'!$E:$E,"-",0) -> 1.0175922e+09 | AJ6: =_xlfn.XLOOKUP($E6,'[2]Balance económico'!$C:$C,'[2]Balance económico'!$F:$F,"-",0) -> ---- | AK6: =IF(AA6>0,"PPA","-") -> PPA | AL6: {=IFERROR((X6*[2]!Tabla2[Bloque A] + 'BD Centrales 2025'!Y78*[2]!Tabla2[Bloque B] + 'BD Centrales 2025'!Z78*[2]!Tabla2[Bloque C])*#REF!,"-")} -> - | AM6: =IFERROR(AH6+AL6,"-") -> - | AN6: =IFERROR((AH6+AI6+AJ6)/(SUMIFS($W$2:$W$1194,$E$2:$E$1194,E6)*1000*#REF!),0) -> 0
A7: 6 | B7: CE05G0012 | C7: HP EL RINCON | D7: ASOC. DE CANAL. SOCIEDAD DEL CANAL DE MAIPO | E7: =_xlfn.XLOOKUP(D7,'[2]Coordinados SEN'!$A:$A,'[2]Coordinados SEN'!$B:$B,"-",0) -> 70.009.410-3 | F7: ASOC. DE CANAL. SOCIEDAD DEL CANAL DE MAIPO | G7: =COUNTIFS($D$2:$D$1194,D7) -> 5 | H7: ID 1223 BA S/E CENTRAL FLORIDA 2 12KV BP1 | I7: S/E FLORIDA 110KV | J7: =_xlfn.XLOOKUP(I7,'[2]Barras CMg'!$E$2:$E$1527,'[2]Barras CMg'!$A$2:$A$1527,"------",0,1) -> FLORIDA_______110 | K7: 1 | L7: 2025 | M7: Hidroeléctrica | N7: Minihidro de pasada | O7: Pequeños medio de generación o PMG | P7: Metropolitana de Santiago | Q7: Santiago | R7: La Florida | S7: Operativa – Autodespacho DS88 | T7: 13-04-2007 | U7: 0.289 | V7: 0.284665 | W7: =_xlfn.XLOOKUP(C7,#REF!,#REF!,"S/I",0) -> #REF! | X7: =_xlfn.XLOOKUP($D7,[2]Retiros_dinamica!$F:$F,[2]Retiros_dinamica!B:B,"S/I",0) -> S/I | Y7: =_xlfn.XLOOKUP($D7,[2]Retiros_dinamica!$F:$F,[2]Retiros_dinamica!C:C,"S/I",0) -> S/I | Z7: =_xlfn.XLOOKUP($D7,[2]Retiros_dinamica!$F:$F,[2]Retiros_dinamica!D:D,"S/I",0) -> S/I | AA7: =_xlfn.XLOOKUP($D7,[2]Retiros_dinamica!$F:$F,[2]Retiros_dinamica!E:E,"S/I",0) -> S/I | AB7: =_xlfn.XLOOKUP(C7,[2]CMg!$I$4:$I$106,[2]CMg!$M$4:$M$106,"----",0,1) -> ---- | AC7: =_xlfn.XLOOKUP(C7,[2]CMg!$A$4:$A$106,[2]CMg!$B$4:$B$106,"----",0,1) -> ---- | AD7: =_xlfn.XLOOKUP(C7,'[3]Promedio solar Cmg'!$A$4:$A$106,'[3]Promedio solar Cmg'!$B$4:$B$106,"----",0,1) -> ---- | AH7: =_xlfn.XLOOKUP($E7,'[2]Balance económico'!$C:$C,'[2]Balance económico'!$D:$D,"-",0) -> 4.1842232e+09 | AI7: =_xlfn.XLOOKUP($E7,'[2]Balance económico'!$C:$C,'[2]Balance económico'!$E:$E,"-",0) -> 4.937221e+08 | AJ7: =_xlfn.XLOOKUP($E7,'[2]Balance económico'!$C:$C,'[2]Balance económico'!$F:$F,"-",0) -> ---- | AK7: =IF(AA7>0,"PPA","-") -> PPA | AL7: {=IFERROR((X7*[2]!Tabla2[Bloque A] + 'BD Centrales 2025'!Y50*[2]!Tabla2[Bloque B] + 'BD Centrales 2025'!Z50*[2]!Tabla2[Bloque C])*#REF!,"-")} -> - | AM7: =IFERROR(AH7+AL7,"-") -> - | AN7: =IFERROR((AH7+AI7+AJ7)/(SUMIFS($W$2:$W$1194,$E$2:$E$1194,E7)*1000*#REF!),0) -> 0
A8: 7 | B8: CE04G0012 | C8: PMGD HP EYZAGUIRRE | D8: ASOC. DE CANAL. SOCIEDAD DEL CANAL DE MAIPO | E8: =_xlfn.XLOOKUP(D8,'[2]Coordinados SEN'!$A:$A,'[2]Coordinados SEN'!$B:$B,"-",0) -> 70.009.410-3 | F8: ASOC. DE CANAL. SOCIEDAD DEL CANAL DE MAIPO | G8: =COUNTIFS($D$2:$D$1194,D8) -> 5 | H8: ID 1064 BA S/E PUENTE ALTO 12KV BP1 | I8: S/E PUENTE ALTO 12KV | J8: =_xlfn.XLOOKUP(I8,'[2]Barras CMg'!$E$2:$E$1527,'[2]Barras CMg'!$A$2:$A$1527,"------",0,1) -> ------ | K8: 1 | L8: 2025 | M8: Hidroeléctrica | N8: Minihidro de pasada | O8: Pequeños medio de generación distribuida o PMGD | P8: Metropolitana de Santiago | Q8: Cordillera | R8: Puente Alto | S8: Operativa | T8: 01-01-2003 | U8: 1.9 | V8: 1.8715 | W8: =_xlfn.XLOOKUP(C8,#REF!,#REF!,"S/I",0) -> #REF! | X8: =_xlfn.XLOOKUP($D8,[2]Retiros_dinamica!$F:$F,[2]Retiros_dinamica!B:B,"S/I",0) -> S/I | Y8: =_xlfn.XLOOKUP($D8,[2]Retiros_dinamica!$F:$F,[2]Retiros_dinamica!C:C,"S/I",0) -> S/I | Z8: =_xlfn.XLOOKUP($D8,[2]Retiros_dinamica!$F:$F,[2]Retiros_dinamica!D:D,"S/I",0) -> S/I | AA8: =_xlfn.XLOOKUP($D8,[2]Retiros_dinamica!$F:$F,[2]Retiros_dinamica!E:E,"S/I",0) -> S/I | AB8: =_xlfn.XLOOKUP(C8,[2]CMg!$I$4:$I$106,[2]CMg!$M$4:$M$106,"----",0,1) -> ---- | AH8: =_xlfn.XLOOKUP($E8,'[2]Balance económico'!$C:$C,'[2]Balance económico'!$D:$D,"-",0) -> 4.1842232e+09 | AI8: =_xlfn.XLOOKUP($E8,'[2]Balance económico'!$C:$C,'[2]Balance económico'!$E:$E,"-",0) -> 4.937221e+08 | AJ8: =_xlfn.XLOOKUP($E8,'[2]Balance económico'!$C:$C,'[2]Balance económico'!$F:$F,"-",0) -> ---- | AK8: =IF(AA8>0,"PPA","-") -> PPA | AL8: {=IFERROR((X8*[2]!Tabla2[Bloque A] + 'BD Centrales 2025'!Y929*[2]!Tabla2[Bloque B] + 'BD Centrales 2025'!Z929*[2]!Tabla2[Bloque C])*#REF!,"-")} -> - | AM8: =IFERROR(AH8+AL8,"-") -> - | AN8: =IFERROR((AH8+AI8+AJ8)/(SUMIFS($W$2:$W$1194,$E$2:$E$1194,E8)*1000*#REF!),0) -> 0
A9: 8 | B9: CE01G0031 | C9: TER CONCON | D9: TECNORED S.A. | E9: =_xlfn.XLOOKUP(D9,'[2]Coordinados SEN'!$A:$A,'[2]Coordinados SEN'!$B:$B,"-",0) -> 77.302.440-5 | F9: TECNORED S.A. | G9: =COUNTIFS($D$2:$D$1194,D9) -> 7 | H9: S/E CONCON 12kV | I9: S/E CONCON 12KV | J9: =_xlfn.XLOOKUP(I9,'[2]Barras CMg'!$E$2:$E$1527,'[2]Barras CMg'!$A$2:$A$1527,"------",0,1) -> CONCON________013 | K9: 3 | L9: 2025 | M9: Termoeléctrica | N9: Motor de combustión interna | O9: Pequeños medio de generación o PMG | P9: Valparaíso | Q9: Valparaíso | R9: Concón | S9: Operativa | T9: 23-04-2007 | U9: 2.489 | V9: 2.489 | W9: =_xlfn.XLOOKUP(C9,#REF!,#REF!,"S/I",0) -> #REF! | X9: =_xlfn.XLOOKUP($D9,[2]Retiros_dinamica!$F:$F,[2]Retiros_dinamica!B:B,"S/I",0) -> 25998.519 | Y9: =_xlfn.XLOOKUP($D9,[2]Retiros_dinamica!$F:$F,[2]Retiros_dinamica!C:C,"S/I",0) -> 36744.498 | Z9: =_xlfn.XLOOKUP($D9,[2]Retiros_dinamica!$F:$F,[2]Retiros_dinamica!D:D,"S/I",0) -> 13134.763 | AA9: =_xlfn.XLOOKUP($D9,[2]Retiros_dinamica!$F:$F,[2]Retiros_dinamica!E:E,"S/I",0) -> 75877.78 | AB9: =_xlfn.XLOOKUP(C9,[2]CMg!$I$4:$I$106,[2]CMg!$M$4:$M$106,"----",0,1) -> ---- | AH9: =_xlfn.XLOOKUP($E9,'[2]Balance económico'!$C:$C,'[2]Balance económico'!$D:$D,"-",0) -> -4.1482077e+09 | AI9: =_xlfn.XLOOKUP($E9,'[2]Balance económico'!$C:$C,'[2]Balance económico'!$E:$E,"-",0) -> 5.9046621e+08 | AJ9: =_xlfn.XLOOKUP($E9,'[2]Balance económico'!$C:$C,'[2]Balance económico'!$F:$F,"-",0) -> 2.2299489e+08 | AK9: =IF(AA9>0,"PPA","-") -> PPA | AL9: {=IFERROR((X9*[2]!Tabla2[Bloque A] + 'BD Centrales 2025'!Y1074*[2]!Tabla2[Bloque B] + 'BD Centrales 2025'!Z1074*[2]!Tabla2[Bloque C])*#REF!,"-")} -> - | AM9: =IFERROR(AH9+AL9,"-") -> - | AN9: =IFERROR((AH9+AI9+AJ9)/(SUMIFS($W$2:$W$1194,$E$2:$E$1194,E9)*1000*#REF!),0) -> 0
A10: 9 | B10: CE07G0031 | C10: TER EL TOTORAL | D10: TECNORED S.A. | E10: =_xlfn.XLOOKUP(D10,'[2]Coordinados SEN'!$A:$A,'[2]Coordinados SEN'!$B:$B,"-",0) -> 77.302.440-5 | F10: TECNORED S.A. | G10: =COUNTIFS($D$2:$D$1194,D10) -> 7 | H10: ID 1079 BA S/E EL TOTORAL 12KV BP1 | I10: S/E EL TOTORAL 12KV | J10: =_xlfn.XLOOKUP(I10,'[2]Barras CMg'!$E$2:$E$1527,'[2]Barras CMg'!$A$2:$A$1527,"------",0,1) -> TOTORAL_______012 | K10: 3 | L10: 2025 | M10: Termoeléctrica | N10: Motor de combustión interna | O10: PMG | P10: Valparaíso | Q10: San Antonio | R10: El Quisco | S10: Operativa | T10: 07-04-2008 | U10: 3.103 | V10: 3.103 | W10: =_xlfn.XLOOKUP(C10,#REF!,#REF!,"S/I",0) -> #REF! | X10: =_xlfn.XLOOKUP($D10,[2]Retiros_dinamica!$F:$F,[2]Retiros_dinamica!B:B,"S/I",0) -> 25998.519 | Y10: =_xlfn.XLOOKUP($D10,[2]Retiros_dinamica!$F:$F,[2]Retiros_dinamica!C:C,"S/I",0) -> 36744.498 | Z10: =_xlfn.XLOOKUP($D10,[2]Retiros_dinamica!$F:$F,[2]Retiros_dinamica!D:D,"S/I",0) -> 13134.763 | AA10: =_xlfn.XLOOKUP($D10,[2]Retiros_dinamica!$F:$F,[2]Retiros_dinamica!E:E,"S/I",0) -> 75877.78 | AB10: =_xlfn.XLOOKUP(C10,[2]CMg!$I$4:$I$106,[2]CMg!$M$4:$M$106,"----",0,1) -> ---- | AH10: =_xlfn.XLOOKUP($E10,'[2]Balance económico'!$C:$C,'[2]Balance económico'!$D:$D,"-",0) -> -4.1482077e+09 | AI10: =_xlfn.XLOOKUP($E10,'[2]Balance económico'!$C:$C,'[2]Balance económico'!$E:$E,"-",0) -> 5.9046621e+08 | AJ10: =_xlfn.XLOOKUP($E10,'[2]Balance económico'!$C:$C,'[2]Balance económico'!$F:$F,"-",0) -> 2.2299489e+08 | AK10: =IF(AA10>0,"PPA","-") -> PPA | AL10: {=IFERROR((X10*[2]!Tabla2[Bloque A] + 'BD Centrales 2025'!Y1097*[2]!Tabla2[Bloque B] + 'BD Centrales 2025'!Z1097*[2]!Tabla2[Bloque C])*#REF!,"-")} -> - | AM10: =IFERROR(AH10+AL10,"-") -> - | AN10: =IFERROR((AH10+AI10+AJ10)/(SUMIFS($W$2:$W$1194,$E$2:$E$1194,E10)*1000*#REF!),0) -> 0
A11: 10 | B11: CE02G0031 | C11: TER LAS VEGAS | D11: TECNORED S.A. | E11: =_xlfn.XLOOKUP(D11,'[2]Coordinados SEN'!$A:$A,'[2]Coordinados SEN'!$B:$B,"-",0) -> 77.302.440-5 | F11: TECNORED S.A. | G11: =COUNTIFS($D$2:$D$1194,D11) -> 7 | H11: S/E LAS VEGAS 110kv | I11: S/E LAS VEGAS (CHILQUINTA) 110KV | J11: =_xlfn.XLOOKUP(I11,'[2]Barras CMg'!$E$2:$E$1527,'[2]Barras CMg'!$A$2:$A$1527,"------",0,1) -> L.VEGAS2______110 | K11: 2 | L11: 2025 | M11: Termoeléctrica | N11: Motor de combustión interna | O11: Pequeños medio de generación o PMG | P11: Valparaíso | Q11: San Felipe de Aconcagua | R11: Llaillay | S11: Operativa | T11: 20-04-2007 | U11: 2.209 | V11: 2.209 | W11: =_xlfn.XLOOKUP(C11,#REF!,#REF!,"S/I",0) -> #REF! | X11: =_xlfn.XLOOKUP($D11,[2]Retiros_dinamica!$F:$F,[2]Retiros_dinamica!B:B,"S/I",0) -> 25998.519 | Y11: =_xlfn.XLOOKUP($D11,[2]Retiros_dinamica!$F:$F,[2]Retiros_dinamica!C:C,"S/I",0) -> 36744.498 | Z11: =_xlfn.XLOOKUP($D11,[2]Retiros_dinamica!$F:$F,[2]Retiros_dinamica!D:D,"S/I",0) -> 13134.763 | AA11: =_xlfn.XLOOKUP($D11,[2]Retiros_dinamica!$F:$F,[2]Retiros_dinamica!E:E,"S/I",0) -> 75877.78 | AB11: =_xlfn.XLOOKUP(C11,[2]CMg!$I$4:$I$106,[2]CMg!$M$4:$M$106,"----",0,1) -> ---- | AH11: =_xlfn.XLOOKUP($E11,'[2]Balance económico'!$C:$C,'[2]Balance económico'!$D:$D,"-",0) -> -4.1482077e+09 | AI11: =_xlfn.XLOOKUP($E11,'[2]Balance económico'!$C:$C,'[2]Balance económico'!$E:$E,"-",0) -> 5.9046621e+08 | AJ11: =_xlfn.XLOOKUP($E11,'[2]Balance económico'!$C:$C,'[2]Balance económico'!$F:$F,"-",0) -> 2.2299489e+08 | AK11: =IF(AA11>0,"PPA","-") -> PPA | AL11: {=IFERROR((X11*[2]!Tabla2[Bloque A] + 'BD Centrales 2025'!Y1126*[2]!Tabla2[Bloque B] + 'BD Centrales 2025'!Z1126*[2]!Tabla2[Bloque C])*#REF!,"-")} -> - | AM11: =IFERROR(AH11+AL11,"-") -> - | AN11: =IFERROR((AH11+AI11+AJ11)/(SUMIFS($W$2:$W$1194,$E$2:$E$1194,E11)*1000*#REF!),0) -> 0
A12: 11 | B12: CE09G0031 | C12: TER LINARES NORTE | D12: CGE COMERCIALIZADORA SPA | E12: =_xlfn.XLOOKUP(D12,'[2]Coordinados SEN'!$A:$A,'[2]Coordinados SEN'!$B:$B,"-",0) -> 77.316.204-2 | F12: TECNORED S.A. | G12: =COUNTIFS($D$2:$D$1194,D12) -> 1 | H12: S/E LINARES NORTE 13.2kV | I12: S/E LINARES NORTE 13.2KV | J12: =_xlfn.XLOOKUP(I12,'[2]Barras CMg'!$E$2:$E$1527,'[2]Barras CMg'!$A$2:$A$1527,"------",0,1) -> LIN.NORTE_____013 | K12: 1 | L12: 2025 | M12: Termoeléctrica | N12: Motor de combustión interna | O12: Pequeños medio de generación o PMG | P12: Maule | Q12: Linares | R12: Linares | S12: Operativa | T12: 20-03-2009 | U12: 0.467 | V12: 0.464 | W12: =_xlfn.XLOOKUP(C12,#REF!,#REF!,"S/I",0) -> #REF! | X12: =_xlfn.XLOOKUP($D12,[2]Retiros_dinamica!$F:$F,[2]Retiros_dinamica!B:B,"S/I",0) -> 23670.829 | Y12: =_xlfn.XLOOKUP($D12,[2]Retiros_dinamica!$F:$F,[2]Retiros_dinamica!C:C,"S/I",0) -> 34683.872 | Z12: =_xlfn.XLOOKUP($D12,[2]Retiros_dinamica!$F:$F,[2]Retiros_dinamica!D:D,"S/I",0) -> 13870.15 | AA12: =_xlfn.XLOOKUP($D12,[2]Retiros_dinamica!$F:$F,[2]Retiros_dinamica!E:E,"S/I",0) -> 72224.851 | AB12: =_xlfn.XLOOKUP(C12,[2]CMg!$I$4:$I$106,[2]CMg!$M$4:$M$106,"----",0,1) -> ---- | AH12: =_xlfn.XLOOKUP($E12,'[2]Balance económico'!$C:$C,'[2]Balance económico'!$D:$D,"-",0) -> -3.7105784e+09 | AI12: =_xlfn.XLOOKUP($E12,'[2]Balance económico'!$C:$C,'[2]Balance económico'!$E:$E,"-",0) -> -6.9608429e+08 | AJ12: =_xlfn.XLOOKUP($E12,'[2]Balance económico'!$C:$C,'[2]Balance económico'!$F:$F,"-",0) -> 2.0931587e+08 | AK12: =IF(AA12>0,"PPA","-") -> PPA | AL12: {=IFERROR((X12*[2]!Tabla2[Bloque A] + 'BD Centrales 2025'!Y1129*[2]!Tabla2[Bloque B] + 'BD Centrales 2025'!Z1129*[2]!Tabla2[Bloque C])*#REF!,"-")} -> - | AM12: =IFERROR(AH12+AL12,"-") -> - | AN12: =IFERROR((AH12+AI12+AJ12)/(SUMIFS($W$2:$W$1194,$E$2:$E$1194,E12)*1000*#REF!),0) -> 0
A13: 12 | B13: CE06G0031 | C13: TER PLACILLA | D13: ENERQUINTA S.A. | E13: =_xlfn.XLOOKUP(D13,'[2]Coordinados SEN'!$A:$A,'[2]Coordinados SEN'!$B:$B,"-",0) -> 77.402.185-K | F13: TECNORED S.A. | G13: =COUNTIFS($D$2:$D$1194,D13) -> 1 | H13: ID 3162 BA S/E PLACILLA (CHILQUINTA) 12KV BP1 | I13: S/E PLACILLA (CHILQUINTA) 12KV | J13: =_xlfn.XLOOKUP(I13,'[2]Barras CMg'!$E$2:$E$1527,'[2]Barras CMg'!$A$2:$A$1527,"------",0,1) -> PLACILLA_S____013 | K13: 2 | L13: 2025 | M13: Termoeléctrica | N13: Motor de combustión interna | O13: Pequeños medio de generación o PMG | P13: Valparaíso | Q13: Valparaíso | R13: Valparaíso | S13: Operativa | T13: 02-05-2008 | U13: 2.373 | V13: 2.373 | W13: =_xlfn.XLOOKUP(C13,#REF!,#REF!,"S/I",0) -> #REF! | X13: =_xlfn.XLOOKUP($D13,[2]Retiros_dinamica!$F:$F,[2]Retiros_dinamica!B:B,"S/I",0) -> 5461.8907 | Y13: =_xlfn.XLOOKUP($D13,[2]Retiros_dinamica!$F:$F,[2]Retiros_dinamica!C:C,"S/I",0) -> 9601.5787 | Z13: =_xlfn.XLOOKUP($D13,[2]Retiros_dinamica!$F:$F,[2]Retiros_dinamica!D:D,"S/I",0) -> 2922.7911 | AA13: =_xlfn.XLOOKUP($D13,[2]Retiros_dinamica!$F:$F,[2]Retiros_dinamica!E:E,"S/I",0) -> 17986.261 | AB13: =_xlfn.XLOOKUP(C13,[2]CMg!$I$4:$I$106,[2]CMg!$M$4:$M$106,"----",0,1) -> ---- | AH13: =_xlfn.XLOOKUP($E13,'[2]Balance económico'!$C:$C,'[2]Balance económico'!$D:$D,"-",0) -> 98284160 | AI13: =_xlfn.XLOOKUP($E13,'[2]Balance económico'!$C:$C,'[2]Balance económico'!$E:$E,"-",0) -> -1.5092092e+08 | AJ13: =_xlfn.XLOOKUP($E13,'[2]Balance económico'!$C:$C,'[2]Balance económico'!$F:$F,"-",0) -> 53787478 | AK13: =IF(AA13>0,"PPA","-") -> PPA | AL13: {=IFERROR((X13*[2]!Tabla2[Bloque A] + 'BD Centrales 2025'!Y1159*[2]!Tabla2[Bloque B] + 'BD Centrales 2025'!Z1159*[2]!Tabla2[Bloque C])*#REF!,"-")} -> - | AM13: =IFERROR(AH13+AL13,"-") -> - | AN13: =IFERROR((AH13+AI13+AJ13)/(SUMIFS($W$2:$W$1194,$E$2:$E$1194,E13)*1000*#REF!),0) -> 0
A14: 14 | B14: CE08G0031 | C14: TER SAN GREGORIO | D14: TECNORED S.A. | E14: =_xlfn.XLOOKUP(D14,'[2]Coordinados SEN'!$A:$A,'[2]Coordinados SEN'!$B:$B,"-",0) -> 77.302.440-5 | F14: TECNORED S.A. | G14: =COUNTIFS($D$2:$D$1194,D14) -> 7 | H14: S/E SAN GREGORIO 13.2kV | I14: S/E SAN GREGORIO 13.2KV | J14: =_xlfn.XLOOKUP(I14,'[2]Barras CMg'!$E$2:$E$1527,'[2]Barras CMg'!$A$2:$A$1527,"------",0,1) -> S.GREGORIO____013 | K14: 1 | L14: 2025 | M14: Termoeléctrica | N14: Motor de combustión interna | O14: Pequeños medio de generación o PMG | P14: Ñuble | Q14: Punilla | R14: Ñiquén | S14: Operativa | T14: 20-03-2009 | U14: 0.425 | V14: 0.422 | W14: =_xlfn.XLOOKUP(C14,#REF!,#REF!,"S/I",0) -> #REF! | X14: =_xlfn.XLOOKUP($D14,[2]Retiros_dinamica!$F:$F,[2]Retiros_dinamica!B:B,"S/I",0) -> 25998.519 | Y14: =_xlfn.XLOOKUP($D14,[2]Retiros_dinamica!$F:$F,[2]Retiros_dinamica!C:C,"S/I",0) -> 36744.498 | Z14: =_xlfn.XLOOKUP($D14,[2]Retiros_dinamica!$F:$F,[2]Retiros_dinamica!D:D,"S/I",0) -> 13134.763 | AA14: =_xlfn.XLOOKUP($D14,[2]Retiros_dinamica!$F:$F,[2]Retiros_dinamica!E:E,"S/I",0) -> 75877.78 | AB14: =_xlfn.XLOOKUP(C14,[2]CMg!$I$4:$I$106,[2]CMg!$M$4:$M$106,"----",0,1) -> ---- | AH14: =_xlfn.XLOOKUP($E14,'[2]Balance económico'!$C:$C,'[2]Balance económico'!$D:$D,"-",0) -> -4.1482077e+09 | AI14: =_xlfn.XLOOKUP($E14,'[2]Balance económico'!$C:$C,'[2]Balance económico'!$E:$E,"-",0) -> 5.9046621e+08 | AJ14: =_xlfn.XLOOKUP($E14,'[2]Balance económico'!$C:$C,'[2]Balance económico'!$F:$F,"-",0) -> 2.2299489e+08 | AK14: =IF(AA14>0,"PPA","-") -> PPA | AL14: {=IFERROR((X14*[2]!Tabla2[Bloque A] + 'BD Centrales 2025'!Y1164*[2]!Tabla2[Bloque B] + 'BD Centrales 2025'!Z1164*[2]!Tabla2[Bloque C])*#REF!,"-")} -> - | AM14: =IFERROR(AH14+AL14,"-") -> - | AN14: =IFERROR((AH14+AI14+AJ14)/(SUMIFS($W$2:$W$1194,$E$2:$E$1194,E14)*1000*#REF!),0) -> 0
A15: 15 | B15: CE01G0022 | C15: PMGD HP AUXILIAR DEL MAIPO | D15: CARBOMET ENERGÍA S.A. | E15: =_xlfn.XLOOKUP(D15,'[2]Coordinados SEN'!$A:$A,'[2]Coordinados SEN'!$B:$B,"-",0) -> 91.066.000-4 | F15: CARBOMET ENERGÍA S.A. | G15: =COUNTIFS($D$2:$D$1194,D15) -> 2 | H15: Alimentador El Mariscal / SE La Pintana | I15: S/E LA PINTANA | J15: =_xlfn.XLOOKUP(I15,'[2]Barras CMg'!$E$2:$E$1527,'[2]Barras CMg'!$A$2:$A$1527,"------",0,1) -> ------ | K15: 3 | L15: 2025 | M15: Hidroeléctrica | N15: Minihidro de pasada | O15: Pequeños medio de generación distribuida o PMGD | P15: Metropolitana de Santiago | Q15: Maipo | R15: San Bernardo | S15: Operativa | T15: 31-07-1962 | U15: 5.12 | V15: 5.1 | W15: =_xlfn.XLOOKUP(C15,#REF!,#REF!,"S/I",0) -> #REF! | X15: =_xlfn.XLOOKUP($D15,[2]Retiros_dinamica!$F:$F,[2]Retiros_dinamica!B:B,"S/I",0) -> S/I | Y15: =_xlfn.XLOOKUP($D15,[2]Retiros_dinamica!$F:$F,[2]Retiros_dinamica!C:C,"S/I",0) -> S/I | Z15: =_xlfn.XLOOKUP($D15,[2]Retiros_dinamica!$F:$F,[2]Retiros_dinamica!D:D,"S/I",0) -> S/I | AA15: =_xlfn.XLOOKUP($D15,[2]Retiros_dinamica!$F:$F,[2]Retiros_dinamica!E:E,"S/I",0) -> S/I | AB15: =_xlfn.XLOOKUP(C15,[2]CMg!$I$4:$I$106,[2]CMg!$M$4:$M$106,"----",0,1) -> ---- | AH15: =_xlfn.XLOOKUP($E15,'[2]Balance económico'!$C:$C,'[2]Balance económico'!$D:$D,"-",0) -> 3.6019824e+09 | AI15: =_xlfn.XLOOKUP($E15,'[2]Balance económico'!$C:$C,'[2]Balance económico'!$E:$E,"-",0) -> 4.573145e+08 | AJ15: =_xlfn.XLOOKUP($E15,'[2]Balance económico'!$C:$C,'[2]Balance económico'!$F:$F,"-",0) -> ---- | AK15: =IF(AA15>0,"PPA","-") -> PPA | AL15: {=IFERROR((X15*[2]!Tabla2[Bloque A] + 'BD Centrales 2025'!Y926*[2]!Tabla2[Bloque B] + 'BD Centrales 2025'!Z926*[2]!Tabla2[Bloque C])*#REF!,"-")} -> - | AM15: =IFERROR(AH15+AL15,"-") -> - | AN15: =IFERROR((AH15+AI15+AJ15)/(SUMIFS($W$2:$W$1194,$E$2:$E$1194,E15)*1000*#REF!),0) -> 0
A16: 16 | B16: CE02G0022 | C16: PMGD HP LOS BAJOS | D16: CARBOMET ENERGÍA S.A. | E16: =_xlfn.XLOOKUP(D16,'[2]Coordinados SEN'!$A:$A,'[2]Coordinados SEN'!$B:$B,"-",0) -> 91.066.000-4 | F16: CARBOMET ENERGÍA S.A. | G16: =COUNTIFS($D$2:$D$1194,D16) -> 2 | H16: S/E CARBOMET 12 KV | I16: S/E CARBOMET 12KV | J16: =_xlfn.XLOOKUP(I16,'[2]Barras CMg'!$E$2:$E$1527,'[2]Barras CMg'!$A$2:$A$1527,"------",0,1) -> ------ | K16: 1 | L16: 2025 | M16: Hidroeléctrica | N16: Minihidro de pasada | O16: Pequeños medio de generación distribuida o PMGD | P16: Metropolitana de Santiago | Q16: Cordillera | R16: Puente Alto | S16: Operativa | T16: 31-07-1944 | U16: 5.5 | V16: 5.4725 | W16: =_xlfn.XLOOKUP(C16,#REF!,#REF!,"S/I",0) -> #REF! | X16: =_xlfn.XLOOKUP($D16,[2]Retiros_dinamica!$F:$F,[2]Retiros_dinamica!B:B,"S/I",0) -> S/I | Y16: =_xlfn.XLOOKUP($D16,[2]Retiros_dinamica!$F:$F,[2]Retiros_dinamica!C:C,"S/I",0) -> S/I | Z16: =_xlfn.XLOOKUP($D16,[2]Retiros_dinamica!$F:$F,[2]Retiros_dinamica!D:D,"S/I",0) -> S/I | AA16: =_xlfn.XLOOKUP($D16,[2]Retiros_dinamica!$F:$F,[2]Retiros_dinamica!E:E,"S/I",0) -> S/I | AB16: =_xlfn.XLOOKUP(C16,[2]CMg!$I$4:$I$106,[2]CMg!$M$4:$M$106,"----",0,1) -> ---- | AH16: =_xlfn.XLOOKUP($E16,'[2]Balance económico'!$C:$C,'[2]Balance económico'!$D:$D,"-",0) -> 3.6019824e+09 | AI16: =_xlfn.XLOOKUP($E16,'[2]Balance económico'!$C:$C,'[2]Balance económico'!$E:$E,"-",0) -> 4.573145e+08 | AJ16: =_xlfn.XLOOKUP($E16,'[2]Balance económico'!$C:$C,'[2]Balance económico'!$F:$F,"-",0) -> ---- | AK16: =IF(AA16>0,"PPA","-") -> PPA | AL16: {=IFERROR((X16*[2]!Tabla2[Bloque A] + 'BD Centrales 2025'!Y927*[2]!Tabla2[Bloque B] + 'BD Centrales 2025'!Z927*[2]!Tabla2[Bloque C])*#REF!,"-")} -> - | AM16: =IFERROR(AH16+AL16,"-") -> - | AN16: =IFERROR((AH16+AI16+AJ16)/(SUMIFS($W$2:$W$1194,$E$2:$E$1194,E16)*1000*#REF!),0) -> 0
A17: 17 | B17: CE01G0023 | C17: PMGD HP LOS MORROS | D17: CIA MOLINERA VILLARRICA LTDA | E17: =_xlfn.XLOOKUP(D17,'[2]Coordinados SEN'!$A:$A,'[2]Coordinados SEN'!$B:$B,"-",0) -> 80.203.400-8 | F17: CIA MOLINERA VILLARRICA LTDA | G17: =COUNTIFS($D$2:$D$1194,D17) -> 2 | H17: S/E LOS MORROS | I17: S/E LOS MORROS | J17: =_xlfn.XLOOKUP(I17,'[2]Barras CMg'!$E$2:$E$1527,'[2]Barras CMg'!$A$2:$A$1527,"------",0,1) -> ------ | K17: 5 | L17: 2025 | M17: Hidroeléctrica | N17: Minihidro de pasada | O17: Pequeños medio de generación distribuida o PMGD | P17: Metropolitana de Santiago | Q17: Maipo | R17: San Bernardo | S17: Operativa | T17: 31-07-1930 | U17: 3.1 | V17: 3.0535 | W17: =_xlfn.XLOOKUP(C17,#REF!,#REF!,"S/I",0) -> #REF! | X17: =_xlfn.XLOOKUP($D17,[2]Retiros_dinamica!$F:$F,[2]Retiros_dinamica!B:B,"S/I",0) -> S/I | Y17: =_xlfn.XLOOKUP($D17,[2]Retiros_dinamica!$F:$F,[2]Retiros_dinamica!C:C,"S/I",0) -> S/I | Z17: =_xlfn.XLOOKUP($D17,[2]Retiros_dinamica!$F:$F,[2]Retiros_dinamica!D:D,"S/I",0) -> S/I | AA17: =_xlfn.XLOOKUP($D17,[2]Retiros_dinamica!$F:$F,[2]Retiros_dinamica!E:E,"S/I",0) -> S/I | AB17: =_xlfn.XLOOKUP(C17,[2]CMg!$I$4:$I$106,[2]CMg!$M$4:$M$106,"----",0,1) -> ---- | AH17: =_xlfn.XLOOKUP($E17,'[2]Balance económico'!$C:$C,'[2]Balance económico'!$D:$D,"-",0) -> 97946755 | AI17: =_xlfn.XLOOKUP($E17,'[2]Balance económico'!$C:$C,'[2]Balance económico'!$E:$E,"-",0) -> 11282345 | AJ17: =_xlfn.XLOOKUP($E17,'[2]Balance económico'!$C:$C,'[2]Balance económico'!$F:$F,"-",0) -> ---- | AK17: =IF(AA17>0,"PPA","-") -> PPA | AL17: {=IFERROR((X17*[2]!Tabla2[Bloque A] + 'BD Centrales 2025'!Y846*[2]!Tabla2[Bloque B] + 'BD Centrales 2025'!Z846*[2]!Tabla2[Bloque C])*#REF!,"-")} -> - | AM17: =IFERROR(AH17+AL17,"-") -> - | AN17: =IFERROR((AH17+AI17+AJ17)/(SUMIFS($W$2:$W$1194,$E$2:$E$1194,E17)*1000*#REF!),0) -> 0
A18: 19 | B18: CE01G0053 | C18: PE LEBU | D18: PARQUE EÓLICO LEBU-TORO SPA | E18: =_xlfn.XLOOKUP(D18,'[2]Coordinados SEN'!$A:$A,'[2]Coordinados SEN'!$B:$B,"-",0) -> 76.416.891-7 | F18: PARQUE EÓLICO LEBU-TORO SPA | G18: =COUNTIFS($D$2:$D$1194,D18) -> 2 | H18: S/E LEBU 66 KV | I18: S/E LEBU 66KV | J18: =_xlfn.XLOOKUP(I18,'[2]Barras CMg'!$E$2:$E$1527,'[2]Barras CMg'!$A$2:$A$1527,"------",0,1) -> LEBU__________066 | K18: 9 | L18: 2025 | M18: Eólica | N18: Parque eólico | O18: Pequeños medio de generación o PMG | P18: Biobío | Q18: Arauco | R18: Lebu | S18: Operativa – Autodespacho DS88 | T18: 25-03-2014 | U18: 10.045 | V18: 9.34 | W18: =_xlfn.XLOOKUP(C18,#REF!,#REF!,"S/I",0) -> #REF! | X18: =_xlfn.XLOOKUP($D18,[2]Retiros_dinamica!$F:$F,[2]Retiros_dinamica!B:B,"S/I",0) -> 672.25883 | Y18: =_xlfn.XLOOKUP($D18,[2]Retiros_dinamica!$F:$F,[2]Retiros_dinamica!C:C,"S/I",0) -> 782.1804 | Z18: =_xlfn.XLOOKUP($D18,[2]Retiros_dinamica!$F:$F,[2]Retiros_dinamica!D:D,"S/I",0) -> 335.7069 | AA18: =_xlfn.XLOOKUP($D18,[2]Retiros_dinamica!$F:$F,[2]Retiros_dinamica!E:E,"S/I",0) -> 1790.1461 | AB18: =_xlfn.XLOOKUP(C18,[2]CMg!$I$4:$I$106,[2]CMg!$M$4:$M$106,"----",0,1) -> ---- | AC18: =_xlfn.XLOOKUP(C18,[2]CMg!$A$4:$A$106,[2]CMg!$B$4:$B$106,"----",0,1) -> ---- | AD18: =_xlfn.XLOOKUP(C18,'[3]Promedio solar Cmg'!$A$4:$A$106,'[3]Promedio solar Cmg'!$B$4:$B$106,"----",0,1) -> ---- | AH18: =_xlfn.XLOOKUP($E18,'[2]Balance económico'!$C:$C,'[2]Balance económico'!$D:$D,"-",0) -> 2.3647287e+08 | AI18: =_xlfn.XLOOKUP($E18,'[2]Balance económico'!$C:$C,'[2]Balance económico'!$E:$E,"-",0) -> -1582155.2 | AJ18: =_xlfn.XLOOKUP($E18,'[2]Balance económico'!$C:$C,'[2]Balance económico'!$F:$F,"-",0) -> 5047447.2 | AK18: =IF(AA18>0,"PPA","-") -> PPA | AL18: {=IFERROR((X18*[2]!Tabla2[Bloque A] + 'BD Centrales 2025'!Y654*[2]!Tabla2[Bloque B] + 'BD Centrales 2025'!Z654*[2]!Tabla2[Bloque C])*#REF!,"-")} -> - | AM18: =IFERROR(AH18+AL18,"-") -> - | AN18: =IFERROR((AH18+AI18+AJ18)/(SUMIFS($W$2:$W$1194,$E$2:$E$1194,E18)*1000*#REF!),0) -> 0
A19: 20 | B19: CE01G0080 | C19: PMGD HP DONGUIL | D19: ENERGY ASSET SPA | E19: =_xlfn.XLOOKUP(D19,'[2]Coordinados SEN'!$A:$A,'[2]Coordinados SEN'!$B:$B,"-",0) -> 76.996.007-4 | F19: DONGUIL ENERGÍA S.A. | G19: =COUNTIFS($D$2:$D$1194,D19) -> 1 | H19: S/E PITRUFQUEN | I19: S/E PITRUFQUEN | J19: =_xlfn.XLOOKUP(I19,'[2]Barras CMg'!$E$2:$E$1527,'[2]Barras CMg'!$A$2:$A$1527,"------",0,1) -> ------ | K19: 1 | L19: 2025 | M19: Hidroeléctrica | N19: Minihidro de pasada | O19: Pequeños medio de generación distribuida o PMGD | P19: La Araucanía | Q19: Cautín | R19: Gorbea | S19: Operativa | T19: 28-05-2011 | U19: 0.25 | V19: 0.2494 | W19: =_xlfn.XLOOKUP(C19,#REF!,#REF!,"S/I",0) -> #REF! | X19: =_xlfn.XLOOKUP($D19,[2]Retiros_dinamica!$F:$F,[2]Retiros_dinamica!B:B,"S/I",0) -> 69889.533 | Y19: =_xlfn.XLOOKUP($D19,[2]Retiros_dinamica!$F:$F,[2]Retiros_dinamica!C:C,"S/I",0) -> 103971.18 | Z19: =_xlfn.XLOOKUP($D19,[2]Retiros_dinamica!$F:$F,[2]Retiros_dinamica!D:D,"S/I",0) -> 34990.618 | AA19: =_xlfn.XLOOKUP($D19,[2]Retiros_dinamica!$F:$F,[2]Retiros_dinamica!E:E,"S/I",0) -> 208851.33 | AB19: =_xlfn.XLOOKUP(C19,[2]CMg!$I$4:$I$106,[2]CMg!$M$4:$M$106,"----",0,1) -> ---- | AH19: =_xlfn.XLOOKUP($E19,'[2]Balance económico'!$C:$C,'[2]Balance económico'!$D:$D,"-",0) -> -1.3323336e+10 | AI19: =_xlfn.XLOOKUP($E19,'[2]Balance económico'!$C:$C,'[2]Balance económico'!$E:$E,"-",0) -> -1.3463716e+09 | AJ19: =_xlfn.XLOOKUP($E19,'[2]Balance económico'!$C:$C,'[2]Balance económico'!$F:$F,"-",0) -> 6.1971068e+08 | AK19: =IF(AA19>0,"PPA","-") -> PPA | AL19: {=IFERROR((X19*[2]!Tabla2[Bloque A] + 'BD Centrales 2025'!Y829*[2]!Tabla2[Bloque B] + 'BD Centrales 2025'!Z829*[2]!Tabla2[Bloque C])*#REF!,"-")} -> - | AM19: =IFERROR(AH19+AL19,"-") -> - | AN19: =IFERROR((AH19+AI19+AJ19)/(SUMIFS($W$2:$W$1194,$E$2:$E$1194,E19)*1000*#REF!),0) -> 0
A20: 21 | B20: CE01G0044 | C20: PMGD HP EL MANZANO (MELIPEUCO) | D20: HIDROELÉCTRICA EL MANZANO S.A. | E20: =_xlfn.XLOOKUP(D20,'[2]Coordinados SEN'!$A:$A,'[2]Coordinados SEN'!$B:$B,"-",0) -> 76.803.940-2 | F20: HIDROELÉCTRICA EL MANZANO S.A. | G20: =COUNTIFS($D$2:$D$1194,D20) -> 1 | H20: S/E LICANCO | I20: S/E LICANCO | J20: =_xlfn.XLOOKUP(I20,'[2]Barras CMg'!$E$2:$E$1527,'[2]Barras CMg'!$A$2:$A$1527,"------",0,1) -> ------ | K20: 1 | L20: 2025 | M20: Hidroeléctrica | N20: Minihidro de pasada | O20: Pequeños medio de generación distribuida o PMGD | P20: La Araucanía | Q20: Cautín | R20: Melipeuco | S20: Operativa | T20: 31-07-2008 | U20: 4.85 | V20: 4.85 | W20: =_xlfn.XLOOKUP(C20,#REF!,#REF!,"S/I",0) -> #REF! | X20: =_xlfn.XLOOKUP($D20,[2]Retiros_dinamica!$F:$F,[2]Retiros_dinamica!B:B,"S/I",0) -> S/I | Y20: =_xlfn.XLOOKUP($D20,[2]Retiros_dinamica!$F:$F,[2]Retiros_dinamica!C:C,"S/I",0) -> S/I | Z20: =_xlfn.XLOOKUP($D20,[2]Retiros_dinamica!$F:$F,[2]Retiros_dinamica!D:D,"S/I",0) -> S/I | AA20: =_xlfn.XLOOKUP($D20,[2]Retiros_dinamica!$F:$F,[2]Retiros_dinamica!E:E,"S/I",0) -> S/I | AB20: =_xlfn.XLOOKUP(C20,[2]CMg!$I$4:$I$106,[2]CMg!$M$4:$M$106,"----",0,1) -> ---- | AH20: =_xlfn.XLOOKUP($E20,'[2]Balance económico'!$C:$C,'[2]Balance económico'!$D:$D,"-",0) -> 5.6023304e+08 | AI20: =_xlfn.XLOOKUP($E20,'[2]Balance económico'!$C:$C,'[2]Balance económico'!$E:$E,"-",0) -> 37905656 | AJ20: =_xlfn.XLOOKUP($E20,'[2]Balance económico'!$C:$C,'[2]Balance económico'!$F:$F,"-",0) -> ---- | AK20: =IF(AA20>0,"PPA","-") -> PPA | AL20: {=IFERROR((X20*[2]!Tabla2[Bloque A] + 'BD Centrales 2025'!Y859*[2]!Tabla2[Bloque B] + 'BD Centrales 2025'!Z859*[2]!Tabla2[Bloque C])*#REF!,"-")} -> - | AM20: =IFERROR(AH20+AL20,"-") -> - | AN20: =IFERROR((AH20+AI20+AJ20)/(SUMIFS($W$2:$W$1194,$E$2:$E$1194,E20)*1000*#REF!),0) -> 0
A21: 22 | B21: CE04G0035 | C21: PMGD TER MONTE PATRIA | D21: ELEKTRA GENERACIÓN S.A. | E21: =_xlfn.XLOOKUP(D21,'[2]Coordinados SEN'!$A:$A,'[2]Coordinados SEN'!$B:$B,"-",0) -> 76.594.660-3 | F21: ELEKTRA GENERACIÓN S.A. | G21: =COUNTIFS($D$2:$D$1194,D21) -> 5 | H21: S/E CENTRAL MONTE PATRIA | I21: S/E CENTRAL MONTE PATRIA | J21: =_xlfn.XLOOKUP(I21,'[2]Barras CMg'!$E$2:$E$1527,'[2]Barras CMg'!$A$2:$A$1527,"------",0,1) -> ------ | K21: 8 | L21: 2025 | M21: Termoeléctrica | N21: Motor de combustión interna | O21: Pequeños medio de generación distribuida o PMGD | P21: Coquimbo | Q21: Limarí | R21: Monte Patria | S21: Operativa | T21: 12-07-2007 | U21: 9 | V21: 9 | W21: =_xlfn.XLOOKUP(C21,#REF!,#REF!,"S/I",0) -> #REF! | X21: =_xlfn.XLOOKUP($D21,[2]Retiros_dinamica!$F:$F,[2]Retiros_dinamica!B:B,"S/I",0) -> S/I | Y21: =_xlfn.XLOOKUP($D21,[2]Retiros_dinamica!$F:$F,[2]Retiros_dinamica!C:C,"S/I",0) -> S/I | Z21: =_xlfn.XLOOKUP($D21,[2]Retiros_dinamica!$F:$F,[2]Retiros_dinamica!D:D,"S/I",0) -> S/I | AA21: =_xlfn.XLOOKUP($D21,[2]Retiros_dinamica!$F:$F,[2]Retiros_dinamica!E:E,"S/I",0) -> S/I | AB21: =_xlfn.XLOOKUP(C21,[2]CMg!$I$4:$I$106,[2]CMg!$M$4:$M$106,"----",0,1) -> ---- | AH21: =_xlfn.XLOOKUP($E21,'[2]Balance económico'!$C:$C,'[2]Balance económico'!$D:$D,"-",0) -> 1.0058747e+09 | AI21: =_xlfn.XLOOKUP($E21,'[2]Balance económico'!$C:$C,'[2]Balance económico'!$E:$E,"-",0) -> 2.3067282e+09 | AJ21: =_xlfn.XLOOKUP($E21,'[2]Balance económico'!$C:$C,'[2]Balance económico'!$F:$F,"-",0) -> ---- | AK21: =IF(AA21>0,"PPA","-") -> PPA | AL21: {=IFERROR((X21*[2]!Tabla2[Bloque A] + 'BD Centrales 2025'!Y1135*[2]!Tabla2[Bloque B] + 'BD Centrales 2025'!Z1135*[2]!Tabla2[Bloque C])*#REF!,"-")} -> - | AM21: =IFERROR(AH21+AL21,"-") -> - | AN21: =IFERROR((AH21+AI21+AJ21)/(SUMIFS($W$2:$W$1194,$E$2:$E$1194,E21)*1000*#REF!),0) -> 0
A22: 23 | B22: CE03G0035 | C22: PMGD TER PUNITAQUI | D22: ELEKTRA GENERACIÓN S.A. | E22: =_xlfn.XLOOKUP(D22,'[2]Coordinados SEN'!$A:$A,'[2]Coordinados SEN'!$B:$B,"-",0) -> 76.594.660-3 | F22: ELEKTRA GENERACIÓN S.A. | G22: =COUNTIFS($D$2:$D$1194,D22) -> 5 | H22: S/E PUNITAQUI | I22: S/E PUNITAQUI | J22: =_xlfn.XLOOKUP(I22,'[2]Barras CMg'!$E$2:$E$1527,'[2]Barras CMg'!$A$2:$A$1527,"------",0,1) -> ------ | K22: 6 | L22: 2025 | M22: Termoeléctrica | N22: Motor de combustión interna | O22: Pequeños medio de generación distribuida o PMGD | P22: Coquimbo | Q22: Limarí | R22: Punitaqui | S22: Operativa | T22: 06-07-2007 | U22: 9 | V22: 9 | W22: =_xlfn.XLOOKUP(C22,#REF!,#REF!,"S/I",0) -> #REF! | X22: =_xlfn.XLOOKUP($D22,[2]Retiros_dinamica!$F:$F,[2]Retiros_dinamica!B:B,"S/I",0) -> S/I | Y22: =_xlfn.XLOOKUP($D22,[2]Retiros_dinamica!$F:$F,[2]Retiros_dinamica!C:C,"S/I",0) -> S/I | Z22: =_xlfn.XLOOKUP($D22,[2]Retiros_dinamica!$F:$F,[2]Retiros_dinamica!D:D,"S/I",0) -> S/I | AA22: =_xlfn.XLOOKUP($D22,[2]Retiros_dinamica!$F:$F,[2]Retiros_dinamica!E:E,"S/I",0) -> S/I | AB22: =_xlfn.XLOOKUP(C22,[2]CMg!$I$4:$I$106,[2]CMg!$M$4:$M$106,"----",0,1) -> ---- | AH22: =_xlfn.XLOOKUP($E22,'[2]Balance económico'!$C:$C,'[2]Balance económico'!$D:$D,"-",0) -> 1.0058747e+09 | AI22: =_xlfn.XLOOKUP($E22,'[2]Balance económico'!$C:$C,'[2]Balance económico'!$E:$E,"-",0) -> 2.3067282e+09 | AJ22: =_xlfn.XLOOKUP($E22,'[2]Balance económico'!$C:$C,'[2]Balance económico'!$F:$F,"-",0) -> ---- | AK22: =IF(AA22>0,"PPA","-") -> PPA | AL22: {=IFERROR((X22*[2]!Tabla2[Bloque A] + 'BD Centrales 2025'!Y1136*[2]!Tabla2[Bloque B] + 'BD Centrales 2025'!Z1136*[2]!Tabla2[Bloque C])*#REF!,"-")} -> - | AM22: =IFERROR(AH22+AL22,"-") -> - | AN22: =IFERROR((AH22+AI22+AJ22)/(SUMIFS($W$2:$W$1194,$E$2:$E$1194,E22)*1000*#REF!),0) -> 0
A23: 24 | B23: CE01G0644 | C23: PMGD HP DOÑA HILDA | D23: SONNEDIX ENERGY CHILE SPA | E23: =_xlfn.XLOOKUP(D23,'[2]Coordinados SEN'!$A:$A,'[2]Coordinados SEN'!$B:$B,"-",0) -> 77.009.353-8 | F23: GANADERA Y FORESTAL CARRAN LIMITADA | G23: =COUNTIFS($D$2:$D$1194,D23) -> 2 | H23: S/E PICHIRROPULLI 23KV | I23: S/E PICHIRROPULLI 23KV | J23: =_xlfn.XLOOKUP(I23,'[2]Barras CMg'!$E$2:$E$1527,'[2]Barras CMg'!$A$2:$A$1527,"------",0,1) -> ------ | K23: 1 | L23: 2025 | M23: Hidroeléctrica | N23: Minihidro de pasada | O23: Pequeños medio de generación distribuida o PMGD | P23: Los Ríos | Q23: Ranco | R23: Lago Ranco | S23: Operativa | T23: 20-11-2010 | U23: 0.42 | V23: 0.419 | W23: =_xlfn.XLOOKUP(C23,#REF!,#REF!,"S/I",0) -> #REF! | X23: =_xlfn.XLOOKUP($D23,[2]Retiros_dinamica!$F:$F,[2]Retiros_dinamica!B:B,"S/I",0) -> S/I | Y23: =_xlfn.XLOOKUP($D23,[2]Retiros_dinamica!$F:$F,[2]Retiros_dinamica!C:C,"S/I",0) -> S/I | Z23: =_xlfn.XLOOKUP($D23,[2]Retiros_dinamica!$F:$F,[2]Retiros_dinamica!D:D,"S/I",0) -> S/I | AA23: =_xlfn.XLOOKUP($D23,[2]Retiros_dinamica!$F:$F,[2]Retiros_dinamica!E:E,"S/I",0) -> S/I | AB23: =_xlfn.XLOOKUP(C23,[2]CMg!$I$4:$I$106,[2]CMg!$M$4:$M$106,"----",0,1) -> ---- | AH23: =_xlfn.XLOOKUP($E23,'[2]Balance económico'!$C:$C,'[2]Balance económico'!$D:$D,"-",0) -> 0 | AI23: =_xlfn.XLOOKUP($E23,'[2]Balance económico'!$C:$C,'[2]Balance económico'!$E:$E,"-",0) -> 4379795.5 | AJ23: =_xlfn.XLOOKUP($E23,'[2]Balance económico'!$C:$C,'[2]Balance económico'!$F:$F,"-",0) -> ---- | AK23: =IF(AA23>0,"PPA","-") -> PPA | AL23: {=IFERROR((X23*[2]!Tabla2[Bloque A] + 'BD Centrales 2025'!Y839*[2]!Tabla2[Bloque B] + 'BD Centrales 2025'!Z839*[2]!Tabla2[Bloque C])*#REF!,"-")} -> - | AM23: =IFERROR(AH23+AL23,"-") -> - | AN23: =IFERROR((AH23+AI23+AJ23)/(SUMIFS($W$2:$W$1194,$E$2:$E$1194,E23)*1000*#REF!),0) -> 0
A24: 25 | B24: CE01G0137 | C24: PMGD HP PEHUI | D24: GENERADORA ELÉCTRICA PEHUI LTDA | E24: =_xlfn.XLOOKUP(D24,'[2]Coordinados SEN'!$A:$A,'[2]Coordinados SEN'!$B:$B,"-",0) -> 76.067.554-7 | F24: GENERADORA ELÉCTRICA PEHUI LTDA | G24: =COUNTIFS($D$2:$D$1194,D24) -> 1 | H24: ALIMENTADOR PILMAIQUEN - MANTIHUE 23 KV | I24: ALIMENTADOR PILMAIQUEN - MANTIHUE 23KV | J24: =_xlfn.XLOOKUP(I24,'[2]Barras CMg'!$E$2:$E$1527,'[2]Barras CMg'!$A$2:$A$1527,"------",0,1) -> ------ | K24: 1 | L24: 2025 | M24: Hidroeléctrica | N24: Minihidro de pasada | O24: Pequeños medio de generación distribuida o PMGD | P24: Los Ríos | Q24: Ranco | R24: Río Bueno | S24: Operativa | T24: 31-07-2001 | U24: 1.1 | V24: 1.1 | W24: =_xlfn.XLOOKUP(C24,#REF!,#REF!,"S/I",0) -> #REF! | X24: =_xlfn.XLOOKUP($D24,[2]Retiros_dinamica!$F:$F,[2]Retiros_dinamica!B:B,"S/I",0) -> S/I | Y24: =_xlfn.XLOOKUP($D24,[2]Retiros_dinamica!$F:$F,[2]Retiros_dinamica!C:C,"S/I",0) -> S/I | Z24: =_xlfn.XLOOKUP($D24,[2]Retiros_dinamica!$F:$F,[2]Retiros_dinamica!D:D,"S/I",0) -> S/I | AA24: =_xlfn.XLOOKUP($D24,[2]Retiros_dinamica!$F:$F,[2]Retiros_dinamica!E:E,"S/I",0) -> S/I | AB24: =_xlfn.XLOOKUP(C24,[2]CMg!$I$4:$I$106,[2]CMg!$M$4:$M$106,"----",0,1) -> ---- | AH24: =_xlfn.XLOOKUP($E24,'[2]Balance económico'!$C:$C,'[2]Balance económico'!$D:$D,"-",0) -> -14095.514 | AI24: =_xlfn.XLOOKUP($E24,'[2]Balance económico'!$C:$C,'[2]Balance económico'!$E:$E,"-",0) -> 42595873 | AJ24: =_xlfn.XLOOKUP($E24,'[2]Balance económico'!$C:$C,'[2]Balance económico'!$F:$F,"-",0) -> ---- | AK24: =IF(AA24>0,"PPA","-") -> PPA | AL24: {=IFERROR((X24*[2]!Tabla2[Bloque A] + 'BD Centrales 2025'!Y864*[2]!Tabla2[Bloque B] + 'BD Centrales 2025'!Z864*[2]!Tabla2[Bloque C])*#REF!,"-")} -> - | AM24: =IFERROR(AH24+AL24,"-") -> - | AN24: =IFERROR((AH24+AI24+AJ24)/(SUMIFS($W$2:$W$1194,$E$2:$E$1194,E24)*1000*#REF!),0) -> 0
A25: 27 | B25: CE17G0004 | C25: HP JUNCALITO | D25: COLBÚN S.A. | E25: =_xlfn.XLOOKUP(D25,'[2]Coordinados SEN'!$A:$A,'[2]Coordinados SEN'!$B:$B,"-",0) -> 96.505.760-9 | F25: COLBÚN S.A. | G25: =COUNTIFS($D$2:$D$1194,D25) -> 29 | H25: S/E HORNITOS 220KV | I25: S/E LOS MAQUIS 220KV | J25: =_xlfn.XLOOKUP(I25,'[2]Barras CMg'!$E$2:$E$1527,'[2]Barras CMg'!$A$2:$A$1527,"------",0,1) -> L.MAQUIS______220 | K25: 1 | L25: 2025 | M25: Hidroeléctrica | N25: Minihidro de pasada | O25: Pequeños medio de generación o PMG | P25: Valparaíso | Q25: Los Andes | R25: Los Andes | S25: Operativa | T25: 31-07-1994 | U25: 1.52 | V25: 1.52 | W25: =_xlfn.XLOOKUP(C25,#REF!,#REF!,"S/I",0) -> #REF! | X25: =_xlfn.XLOOKUP($D25,[2]Retiros_dinamica!$F:$F,[2]Retiros_dinamica!B:B,"S/I",0) -> 3718226.1 | Y25: =_xlfn.XLOOKUP($D25,[2]Retiros_dinamica!$F:$F,[2]Retiros_dinamica!C:C,"S/I",0) -> 3629256.6 | Z25: =_xlfn.XLOOKUP($D25,[2]Retiros_dinamica!$F:$F,[2]Retiros_dinamica!D:D,"S/I",0) -> 1641521.7 | AA25: =_xlfn.XLOOKUP($D25,[2]Retiros_dinamica!$F:$F,[2]Retiros_dinamica!E:E,"S/I",0) -> 8989004.4 | AB25: =_xlfn.XLOOKUP(C25,[2]CMg!$I$4:$I$106,[2]CMg!$M$4:$M$106,"----",0,1) -> ---- | AC25: =_xlfn.XLOOKUP(C25,[2]CMg!$A$4:$A$106,[2]CMg!$B$4:$B$106,"----",0,1) -> ---- | AD25: =_xlfn.XLOOKUP(C25,'[3]Promedio solar Cmg'!$A$4:$A$106,'[3]Promedio solar Cmg'!$B$4:$B$106,"----",0,1) -> ---- | AH25: =_xlfn.XLOOKUP($E25,'[2]Balance económico'!$C:$C,'[2]Balance económico'!$D:$D,"-",0) -> -1.345249e+09 | AI25: =_xlfn.XLOOKUP($E25,'[2]Balance económico'!$C:$C,'[2]Balance económico'!$E:$E,"-",0) -> 1.898617e+09 | AJ25: =_xlfn.XLOOKUP($E25,'[2]Balance económico'!$C:$C,'[2]Balance económico'!$F:$F,"-",0) -> 3.0881173e+10 | AK25: =IF(AA25>0,"PPA","-") -> PPA | AL25: {=IFERROR((X25*[2]!Tabla2[Bloque A] + 'BD Centrales 2025'!Y60*[2]!Tabla2[Bloque B] + 'BD Centrales 2025'!Z60*[2]!Tabla2[Bloque C])*#REF!,"-")} -> - | AM25: =IFERROR(AH25+AL25,"-") -> - | AN25: =IFERROR((AH25+AI25+AJ25)/(SUMIFS($W$2:$W$1194,$E$2:$E$1194,E25)*1000*#REF!),0) -> 0
A26: 28 | B26: CE04G0054 | C26: PMGD HP TRUFULTRUFUL | D26: ENERBOSCH S.A. | E26: =_xlfn.XLOOKUP(D26,'[2]Coordinados SEN'!$A:$A,'[2]Coordinados SEN'!$B:$B,"-",0) -> 76.028.873-K | F26: ENERBOSCH S.A. | G26: =COUNTIFS($D$2:$D$1194,D26) -> 5 | H26: ID 1075 BA S/E LICANCO 23KV | I26: S/E LICANCO 23KV | J26: =_xlfn.XLOOKUP(I26,'[2]Barras CMg'!$E$2:$E$1527,'[2]Barras CMg'!$A$2:$A$1527,"------",0,1) -> ------ | K26: 1 | L26: 2025 | M26: Hidroeléctrica | N26: Minihidro de pasada | O26: Pequeños medio de generación distribuida o PMGD | P26: La Araucanía | Q26: Cautín | R26: Melipeuco | S26: Operativa | T26: 16-09-2009 | U26: 0.836 | V26: 0.819 | W26: =_xlfn.XLOOKUP(C26,#REF!,#REF!,"S/I",0) -> #REF! | X26: =_xlfn.XLOOKUP($D26,[2]Retiros_dinamica!$F:$F,[2]Retiros_dinamica!B:B,"S/I",0) -> S/I | Y26: =_xlfn.XLOOKUP($D26,[2]Retiros_dinamica!$F:$F,[2]Retiros_dinamica!C:C,"S/I",0) -> S/I | Z26: =_xlfn.XLOOKUP($D26,[2]Retiros_dinamica!$F:$F,[2]Retiros_dinamica!D:D,"S/I",0) -> S/I | AA26: =_xlfn.XLOOKUP($D26,[2]Retiros_dinamica!$F:$F,[2]Retiros_dinamica!E:E,"S/I",0) -> S/I | AB26: =_xlfn.XLOOKUP(C26,[2]CMg!$I$4:$I$106,[2]CMg!$M$4:$M$106,"----",0,1) -> ---- | AH26: =_xlfn.XLOOKUP($E26,'[2]Balance económico'!$C:$C,'[2]Balance económico'!$D:$D,"-",0) -> 2.6053849e+08 | AI26: =_xlfn.XLOOKUP($E26,'[2]Balance económico'!$C:$C,'[2]Balance económico'!$E:$E,"-",0) -> 2.2312454e+08 | AJ26: =_xlfn.XLOOKUP($E26,'[2]Balance económico'!$C:$C,'[2]Balance económico'!$F:$F,"-",0) -> ---- | AK26: =IF(AA26>0,"PPA","-") -> PPA | AL26: {=IFERROR((X26*[2]!Tabla2[Bloque A] + 'BD Centrales 2025'!Y914*[2]!Tabla2[Bloque B] + 'BD Centrales 2025'!Z914*[2]!Tabla2[Bloque C])*#REF!,"-")} -> - | AM26: =IFERROR(AH26+AL26,"-") -> - | AN26: =IFERROR((AH26+AI26+AJ26)/(SUMIFS($W$2:$W$1194,$E$2:$E$1194,E26)*1000*#REF!),0) -> 0
A27: 29 | B27: CE01G1002 | C27: PMGD HP DONGO | D27: DONGO ENERGÍA SPA | E27: =_xlfn.XLOOKUP(D27,'[2]Coordinados SEN'!$A:$A,'[2]Coordinados SEN'!$B:$B,"-",0) -> 77.930.796-4 | F27: DONGO ENERGÍA SPA | G27: =COUNTIFS($D$2:$D$1194,D27) -> 1 | H27: S/E CENTRAL EL DONGO | I27: S/E CENTRAL EL DONGO | J27: =_xlfn.XLOOKUP(I27,'[2]Barras CMg'!$E$2:$E$1527,'[2]Barras CMg'!$A$2:$A$1527,"------",0,1) -> ------ | K27: 2 | L27: 2025 | M27: Hidroeléctrica | N27: Minihidro de pasada | O27: Pequeños medio de generación distribuida o PMGD | P27: Los Lagos | Q27: Chiloé | R27: Chonchi | S27: Operativa | T27: 14-12-2010 | U27: 6 | V27: 5.9976 | W27: =_xlfn.XLOOKUP(C27,#REF!,#REF!,"S/I",0) -> #REF! | X27: =_xlfn.XLOOKUP($D27,[2]Retiros_dinamica!$F:$F,[2]Retiros_dinamica!B:B,"S/I",0) -> S/I | Y27: =_xlfn.XLOOKUP($D27,[2]Retiros_dinamica!$F:$F,[2]Retiros_dinamica!C:C,"S/I",0) -> S/I | Z27: =_xlfn.XLOOKUP($D27,[2]Retiros_dinamica!$F:$F,[2]Retiros_dinamica!D:D,"S/I",0) -> S/I | AA27: =_xlfn.XLOOKUP($D27,[2]Retiros_dinamica!$F:$F,[2]Retiros_dinamica!E:E,"S/I",0) -> S/I | AB27: =_xlfn.XLOOKUP(C27,[2]CMg!$I$4:$I$106,[2]CMg!$M$4:$M$106,"----",0,1) -> ---- | AH27: =_xlfn.XLOOKUP($E27,'[2]Balance económico'!$C:$C,'[2]Balance económico'!$D:$D,"-",0) -> 21306501 | AI27: =_xlfn.XLOOKUP($E27,'[2]Balance económico'!$C:$C,'[2]Balance económico'!$E:$E,"-",0) -> 2.3285773e+08 | AJ27: =_xlfn.XLOOKUP($E27,'[2]Balance económico'!$C:$C,'[2]Balance económico'!$F:$F,"-",0) -> ---- | AK27: =IF(AA27>0,"PPA","-") -> PPA | AL27: {=IFERROR((X27*[2]!Tabla2[Bloque A] + 'BD Centrales 2025'!Y920*[2]!Tabla2[Bloque B] + 'BD Centrales 2025'!Z920*[2]!Tabla2[Bloque C])*#REF!,"-")} -> - | AM27: =IFERROR(AH27+AL27,"-") -> - | AN27: =IFERROR((AH27+AI27+AJ27)/(SUMIFS($W$2:$W$1194,$E$2:$E$1194,E27)*1000*#REF!),0) -> 0
A28: 30 | B28: CE01G0083 | C28: PMGD HP MALLARAUCO | D28: HIDROELÉCTRICA MALLARAUCO S.A. | E28: =_xlfn.XLOOKUP(D28,'[2]Coordinados SEN'!$A:$A,'[2]Coordinados SEN'!$B:$B,"-",0) -> 76.055.136-8 | F28: HIDROELÉCTRICA MALLARAUCO S.A. | G28: =COUNTIFS($D$2:$D$1194,D28) -> 1 | H28: S/E EL PAICO 13.2KV | I28: S/E EL PAICO 13.2KV | J28: =_xlfn.XLOOKUP(I28,'[2]Barras CMg'!$E$2:$E$1527,'[2]Barras CMg'!$A$2:$A$1527,"------",0,1) -> ELPAICO_______013 | K28: 1 | L28: 2025 | M28: Hidroeléctrica | N28: Minihidro de pasada | O28: Pequeños medio de generación distribuida o PMGD | P28: Metropolitana de Santiago | Q28: Melipilla | R28: Melipilla | S28: Operativa | T28: 24-06-2011 | U28: 3.4 | V28: 3.3915 | W28: =_xlfn.XLOOKUP(C28,#REF!,#REF!,"S/I",0) -> #REF! | X28: =_xlfn.XLOOKUP($D28,[2]Retiros_dinamica!$F:$F,[2]Retiros_dinamica!B:B,"S/I",0) -> S/I | Y28: =_xlfn.XLOOKUP($D28,[2]Retiros_dinamica!$F:$F,[2]Retiros_dinamica!C:C,"S/I",0) -> S/I | Z28: =_xlfn.XLOOKUP($D28,[2]Retiros_dinamica!$F:$F,[2]Retiros_dinamica!D:D,"S/I",0) -> S/I | AA28: =_xlfn.XLOOKUP($D28,[2]Retiros_dinamica!$F:$F,[2]Retiros_dinamica!E:E,"S/I",0) -> S/I | AB28: =_xlfn.XLOOKUP(C28,[2]CMg!$I$4:$I$106,[2]CMg!$M$4:$M$106,"----",0,1) -> ---- | AH28: =_xlfn.XLOOKUP($E28,'[2]Balance económico'!$C:$C,'[2]Balance económico'!$D:$D,"-",0) -> 3.2747515e+08 | AI28: =_xlfn.XLOOKUP($E28,'[2]Balance económico'!$C:$C,'[2]Balance económico'!$E:$E,"-",0) -> 1.9464081e+08 | AJ28: =_xlfn.XLOOKUP($E28,'[2]Balance económico'!$C:$C,'[2]Balance económico'!$F:$F,"-",0) -> ---- | AK28: =IF(AA28>0,"PPA","-") -> PPA | AL28: {=IFERROR((X28*[2]!Tabla2[Bloque A] + 'BD Centrales 2025'!Y907*[2]!Tabla2[Bloque B] + 'BD Centrales 2025'!Z907*[2]!Tabla2[Bloque C])*#REF!,"-")} -> - | AM28: =IFERROR(AH28+AL28,"-") -> - | AN28: =IFERROR((AH28+AI28+AJ28)/(SUMIFS($W$2:$W$1194,$E$2:$E$1194,E28)*1000*#REF!),0) -> 0
A29: 31 | B29: CE01G0063 | C29: PMGD HP RIO TRUENO | D29: HIDROELÉCTRICA TRUENO S.A. | E29: =_xlfn.XLOOKUP(D29,'[2]Coordinados SEN'!$A:$A,'[2]Coordinados SEN'!$B:$B,"-",0) -> 76.834.000-5 | F29: HIDROELÉCTRICA TRUENO S.A. | G29: =COUNTIFS($D$2:$D$1194,D29) -> 1 | H29: S/E LAUTARO 13.2KV | I29: S/E LAUTARO 13.2KV | J29: =_xlfn.XLOOKUP(I29,'[2]Barras CMg'!$E$2:$E$1527,'[2]Barras CMg'!$A$2:$A$1527,"------",0,1) -> LAUTARO_______013 | K29: 2 | L29: 2025 | M29: Hidroeléctrica | N29: Minihidro de pasada | O29: Pequeños medio de generación distribuida o PMGD | P29: La Araucanía | Q29: Cautín | R29: Vilcún | S29: Operativa | T29: 06-06-2010 | U29: 5.6 | V29: 5.59 | W29: =_xlfn.XLOOKUP(C29,#REF!,#REF!,"S/I",0) -> #REF! | X29: =_xlfn.XLOOKUP($D29,[2]Retiros_dinamica!$F:$F,[2]Retiros_dinamica!B:B,"S/I",0) -> S/I | Y29: =_xlfn.XLOOKUP($D29,[2]Retiros_dinamica!$F:$F,[2]Retiros_dinamica!C:C,"S/I",0) -> S/I | Z29: =_xlfn.XLOOKUP($D29,[2]Retiros_dinamica!$F:$F,[2]Retiros_dinamica!D:D,"S/I",0) -> S/I | AA29: =_xlfn.XLOOKUP($D29,[2]Retiros_dinamica!$F:$F,[2]Retiros_dinamica!E:E,"S/I",0) -> S/I | AB29: =_xlfn.XLOOKUP(C29,[2]CMg!$I$4:$I$106,[2]CMg!$M$4:$M$106,"----",0,1) -> ---- | AH29: =_xlfn.XLOOKUP($E29,'[2]Balance económico'!$C:$C,'[2]Balance económico'!$D:$D,"-",0) -> 2.1821042e+08 | AI29: =_xlfn.XLOOKUP($E29,'[2]Balance económico'!$C:$C,'[2]Balance económico'!$E:$E,"-",0) -> 1.197106e+08 | AJ29: =_xlfn.XLOOKUP($E29,'[2]Balance económico'!$C:$C,'[2]Balance económico'!$F:$F,"-",0) -> ---- | AK29: =IF(AA29>0,"PPA","-") -> PPA | AL29: {=IFERROR((X29*[2]!Tabla2[Bloque A] + 'BD Centrales 2025'!Y894*[2]!Tabla2[Bloque B] + 'BD Centrales 2025'!Z894*[2]!Tabla2[Bloque C])*#REF!,"-")} -> - | AM29: =IFERROR(AH29+AL29,"-") -> - | AN29: =IFERROR((AH29+AI29+AJ29)/(SUMIFS($W$2:$W$1194,$E$2:$E$1194,E29)*1000*#REF!),0) -> 0
A30: 32 | B30: CE01G0060 | C30: PMGD HP LA PALOMA | D30: HIDROPALOMA S.A. | E30: =_xlfn.XLOOKUP(D30,'[2]Coordinados SEN'!$A:$A,'[2]Coordinados SEN'!$B:$B,"-",0) -> 76.849.580-7 | F30: HIDROPALOMA S.A. | G30: =COUNTIFS($D$2:$D$1194,D30) -> 1 | H30: S/E MONTE PATRIA 13.2KV | I30: S/E MONTE PATRIA 13.2KV | J30: =_xlfn.XLOOKUP(I30,'[2]Barras CMg'!$E$2:$E$1527,'[2]Barras CMg'!$A$2:$A$1527,"------",0,1) -> M.PATRIA______013 | K30: 2 | L30: 2025 | M30: Hidroeléctrica | N30: Minihidro de pasada | O30: Pequeños medio de generación distribuida o PMGD | P30: Coquimbo | Q30: Limarí | R30: Ovalle | S30: Operativa | T30: 29-03-2010 | U30: 4.6 | V30: 4.416 | W30: =_xlfn.XLOOKUP(C30,#REF!,#REF!,"S/I",0) -> #REF! | X30: =_xlfn.XLOOKUP($D30,[2]Retiros_dinamica!$F:$F,[2]Retiros_dinamica!B:B,"S/I",0) -> S/I | Y30: =_xlfn.XLOOKUP($D30,[2]Retiros_dinamica!$F:$F,[2]Retiros_dinamica!C:C,"S/I",0) -> S/I | Z30: =_xlfn.XLOOKUP($D30,[2]Retiros_dinamica!$F:$F,[2]Retiros_dinamica!D:D,"S/I",0) -> S/I | AA30: =_xlfn.XLOOKUP($D30,[2]Retiros_dinamica!$F:$F,[2]Retiros_dinamica!E:E,"S/I",0) -> S/I | AB30: =_xlfn.XLOOKUP(C30,[2]CMg!$I$4:$I$106,[2]CMg!$M$4:$M$106,"----",0,1) -> ---- | AH30: =_xlfn.XLOOKUP($E30,'[2]Balance económico'!$C:$C,'[2]Balance económico'!$D:$D,"-",0) -> 0 | AI30: =_xlfn.XLOOKUP($E30,'[2]Balance económico'!$C:$C,'[2]Balance económico'!$E:$E,"-",0) -> 1.3552885e+08 | AJ30: =_xlfn.XLOOKUP($E30,'[2]Balance económico'!$C:$C,'[2]Balance económico'!$F:$F,"-",0) -> ---- | AK30: =IF(AA30>0,"PPA","-") -> PPA | AL30: {=IFERROR((X30*[2]!Tabla2[Bloque A] + 'BD Centrales 2025'!Y899*[2]!Tabla2[Bloque B] + 'BD Centrales 2025'!Z899*[2]!Tabla2[Bloque C])*#REF!,"-")} -> - | AM30: =IFERROR(AH30+AL30,"-") -> - | AN30: =IFERROR((AH30+AI30+AJ30)/(SUMIFS($W$2:$W$1194,$E$2:$E$1194,E30)*1000*#REF!),0) -> 0
A31: 35 | B31: CE01G0109 | C31: PMGD HP EL TARTARO | D31: ON-GROUP S.A. | E31: =_xlfn.XLOOKUP(D31,'[2]Coordinados SEN'!$A:$A,'[2]Coordinados SEN'!$B:$B,"-",0) -> 96.827.870-3 | F31: WENKE Y CIA LTDA | G31: =COUNTIFS($D$2:$D$1194,D31) -> 2 | H31: ALIMENTADOR PUTAENDO 12 KV | I31: ALIMENTADOR PUTAENDO 12KV | J31: =_xlfn.XLOOKUP(I31,'[2]Barras CMg'!$E$2:$E$1527,'[2]Barras CMg'!$A$2:$A$1527,"------",0,1) -> ------ | K31: 1 | L31: 2025 | M31: Hidroeléctrica | N31: Minihidro de pasada | O31: Pequeños medio de generación distribuida o PMGD | P31: Valparaíso | Q31: San Felipe de Aconcagua | R31: Putaendo | S31: Operativa | T31: 01-09-2010 | U31: 0.104 | V31: 0.1037 | W31: =_xlfn.XLOOKUP(C31,#REF!,#REF!,"S/I",0) -> #REF! | X31: =_xlfn.XLOOKUP($D31,[2]Retiros_dinamica!$F:$F,[2]Retiros_dinamica!B:B,"S/I",0) -> 8734.4032 | Y31: =_xlfn.XLOOKUP($D31,[2]Retiros_dinamica!$F:$F,[2]Retiros_dinamica!C:C,"S/I",0) -> 9511.5209 | Z31: =_xlfn.XLOOKUP($D31,[2]Retiros_dinamica!$F:$F,[2]Retiros_dinamica!D:D,"S/I",0) -> 4851.7833 | AA31: =_xlfn.XLOOKUP($D31,[2]Retiros_dinamica!$F:$F,[2]Retiros_dinamica!E:E,"S/I",0) -> 23097.707 | AB31: =_xlfn.XLOOKUP(C31,[2]CMg!$I$4:$I$106,[2]CMg!$M$4:$M$106,"----",0,1) -> ---- | AH31: =_xlfn.XLOOKUP($E31,'[2]Balance económico'!$C:$C,'[2]Balance económico'!$D:$D,"-",0) -> -9.6924181e+08 | AI31: =_xlfn.XLOOKUP($E31,'[2]Balance económico'!$C:$C,'[2]Balance económico'!$E:$E,"-",0) -> -1.6593366e+08 | AJ31: =_xlfn.XLOOKUP($E31,'[2]Balance económico'!$C:$C,'[2]Balance económico'!$F:$F,"-",0) -> 65657881 | AK31: =IF(AA31>0,"PPA","-") -> PPA | AL31: {=IFERROR((X31*[2]!Tabla2[Bloque A] + 'BD Centrales 2025'!Y835*[2]!Tabla2[Bloque B] + 'BD Centrales 2025'!Z835*[2]!Tabla2[Bloque C])*#REF!,"-")} -> - | AM31: =IFERROR(AH31+AL31,"-") -> - | AN31: =IFERROR((AH31+AI31+AJ31)/(SUMIFS($W$2:$W$1194,$E$2:$E$1194,E31)*1000*#REF!),0) -> 0
A32: 36 | B32: CE01G0056 | C32: PMGD TER ORAFTI | D32: ORAFTI CHILE S.A. | E32: =_xlfn.XLOOKUP(D32,'[2]Coordinados SEN'!$A:$A,'[2]Coordinados SEN'!$B:$B,"-",0) -> 77.894.990-3 | F32: ORAFTI CHILE S.A. | G32: =COUNTIFS($D$2:$D$1194,D32) -> 1 | H32: Alimentador Bulnes / SE Cabrero | I32: S/E CABRERO | J32: =_xlfn.XLOOKUP(I32,'[2]Barras CMg'!$E$2:$E$1527,'[2]Barras CMg'!$A$2:$A$1527,"------",0,1) -> ------ | K32: 3 | L32: 2025 | M32: Termoeléctrica | N32: Motor de combustión interna | O32: Pequeños medio de generación distribuida o PMGD | P32: Ñuble | Q32: Diguillín | R32: Pemuco | S32: Operativa | T32: 27-02-2009 | U32: 8.2 | V32: 7.2 | W32: =_xlfn.XLOOKUP(C32,#REF!,#REF!,"S/I",0) -> #REF! | X32: =_xlfn.XLOOKUP($D32,[2]Retiros_dinamica!$F:$F,[2]Retiros_dinamica!B:B,"S/I",0) -> S/I | Y32: =_xlfn.XLOOKUP($D32,[2]Retiros_dinamica!$F:$F,[2]Retiros_dinamica!C:C,"S/I",0) -> S/I | Z32: =_xlfn.XLOOKUP($D32,[2]Retiros_dinamica!$F:$F,[2]Retiros_dinamica!D:D,"S/I",0) -> S/I | AA32: =_xlfn.XLOOKUP($D32,[2]Retiros_dinamica!$F:$F,[2]Retiros_dinamica!E:E,"S/I",0) -> S/I | AB32: =_xlfn.XLOOKUP(C32,[2]CMg!$I$4:$I$106,[2]CMg!$M$4:$M$106,"----",0,1) -> ---- | AH32: =_xlfn.XLOOKUP($E32,'[2]Balance económico'!$C:$C,'[2]Balance económico'!$D:$D,"-",0) -> 1.0068583e+08 | AI32: =_xlfn.XLOOKUP($E32,'[2]Balance económico'!$C:$C,'[2]Balance económico'!$E:$E,"-",0) -> ---- | AJ32: =_xlfn.XLOOKUP($E32,'[2]Balance económico'!$C:$C,'[2]Balance económico'!$F:$F,"-",0) -> ---- | AK32: =IF(AA32>0,"PPA","-") -> PPA | AL32: {=IFERROR((X32*[2]!Tabla2[Bloque A] + 'BD Centrales 2025'!Y1193*[2]!Tabla2[Bloque B] + 'BD Centrales 2025'!Z1193*[2]!Tabla2[Bloque C])*#REF!,"-")} -> - | AM32: =IFERROR(AH32+AL32,"-") -> - | AN32: =IFERROR((AH32+AI32+AJ32)/(SUMIFS($W$2:$W$1194,$E$2:$E$1194,E32)*1000*#REF!),0) -> 0
